/home/intellisys/Desktop/demo-app/apps/frappe/frappe/build.py:7: DeprecationWarning: The distutils package is deprecated and slated for removal in Python 3.12. Use setuptools or check PEP 632 for potential alternatives
  from distutils.spawn import find_executable
19:09:31 Traceback (most recent call last):
  File "/home/intellisys/Desktop/demo-app/env/lib/python3.10/site-packages/rq/worker.py", line 1013, in perform_job
    rv = job.perform()
  File "/home/intellisys/Desktop/demo-app/env/lib/python3.10/site-packages/rq/job.py", line 709, in perform
    self._result = self._execute()
  File "/home/intellisys/Desktop/demo-app/env/lib/python3.10/site-packages/rq/job.py", line 732, in _execute
    result = self.func(*self.args, **self.kwargs)
  File "/home/intellisys/Desktop/demo-app/apps/frappe/frappe/utils/background_jobs.py", line 144, in execute_job
    method(**kwargs)
  File "/home/intellisys/Desktop/demo-app/apps/frappe/frappe/core/doctype/user/user.py", line 1132, in create_contact
    contact.insert(
  File "/home/intellisys/Desktop/demo-app/apps/frappe/frappe/model/document.py", line 256, in insert
    self._validate_links()
  File "/home/intellisys/Desktop/demo-app/apps/frappe/frappe/model/document.py", line 909, in _validate_links
    frappe.throw(_("Could not find {0}").format(msg), frappe.LinkValidationError)
  File "/home/intellisys/Desktop/demo-app/apps/frappe/frappe/__init__.py", line 504, in throw
    msgprint(
  File "/home/intellisys/Desktop/demo-app/apps/frappe/frappe/__init__.py", line 479, in msgprint
    _raise_exception()
  File "/home/intellisys/Desktop/demo-app/apps/frappe/frappe/__init__.py", line 434, in _raise_exception
    raise raise_exception(msg)
frappe.exceptions.LinkValidationError: Could not find User Id: lazalajochy@gmail.com

19:09:34 Traceback (most recent call last):
  File "/home/intellisys/Desktop/demo-app/env/lib/python3.10/site-packages/rq/worker.py", line 1013, in perform_job
    rv = job.perform()
  File "/home/intellisys/Desktop/demo-app/env/lib/python3.10/site-packages/rq/job.py", line 709, in perform
    self._result = self._execute()
  File "/home/intellisys/Desktop/demo-app/env/lib/python3.10/site-packages/rq/job.py", line 732, in _execute
    result = self.func(*self.args, **self.kwargs)
  File "/home/intellisys/Desktop/demo-app/apps/frappe/frappe/utils/background_jobs.py", line 144, in execute_job
    method(**kwargs)
  File "/home/intellisys/Desktop/demo-app/apps/frappe/frappe/core/doctype/user/user.py", line 1132, in create_contact
    contact.insert(
  File "/home/intellisys/Desktop/demo-app/apps/frappe/frappe/model/document.py", line 256, in insert
    self._validate_links()
  File "/home/intellisys/Desktop/demo-app/apps/frappe/frappe/model/document.py", line 909, in _validate_links
    frappe.throw(_("Could not find {0}").format(msg), frappe.LinkValidationError)
  File "/home/intellisys/Desktop/demo-app/apps/frappe/frappe/__init__.py", line 504, in throw
    msgprint(
  File "/home/intellisys/Desktop/demo-app/apps/frappe/frappe/__init__.py", line 479, in msgprint
    _raise_exception()
  File "/home/intellisys/Desktop/demo-app/apps/frappe/frappe/__init__.py", line 434, in _raise_exception
    raise raise_exception(msg)
frappe.exceptions.LinkValidationError: Could not find User Id: lazalajochy@gmail.com

Exception in thread Thread-1:
Traceback (most recent call last):
  File "/usr/lib/python3.10/threading.py", line 1016, in _bootstrap_inner
    self.run()
  File "/home/intellisys/Desktop/demo-app/env/lib/python3.10/site-packages/redis/client.py", line 3718, in run
    pubsub.get_message(ignore_subscribe_messages=True,
  File "/home/intellisys/Desktop/demo-app/env/lib/python3.10/site-packages/redis/client.py", line 3617, in get_message
    response = self.parse_response(block=False, timeout=timeout)
  File "/home/intellisys/Desktop/demo-app/env/lib/python3.10/site-packages/redis/client.py", line 3503, in parse_response
    if not block and not conn.can_read(timeout=timeout):
  File "/home/intellisys/Desktop/demo-app/env/lib/python3.10/site-packages/redis/connection.py", line 734, in can_read
    return self._parser.can_read(timeout)
  File "/home/intellisys/Desktop/demo-app/env/lib/python3.10/site-packages/redis/connection.py", line 416, in can_read
    return self.read_from_socket(timeout=timeout,
  File "/home/intellisys/Desktop/demo-app/env/lib/python3.10/site-packages/redis/connection.py", line 429, in read_from_socket
    raise ConnectionError(SERVER_CLOSED_CONNECTION_ERROR)
redis.exceptions.ConnectionError: Connection closed by server.
19:10:26 Traceback (most recent call last):
  File "/home/intellisys/Desktop/demo-app/env/lib/python3.10/site-packages/redis/connection.py", line 1198, in get_connection
    if connection.can_read():
  File "/home/intellisys/Desktop/demo-app/env/lib/python3.10/site-packages/redis/connection.py", line 734, in can_read
    return self._parser.can_read(timeout)
  File "/home/intellisys/Desktop/demo-app/env/lib/python3.10/site-packages/redis/connection.py", line 416, in can_read
    return self.read_from_socket(timeout=timeout,
  File "/home/intellisys/Desktop/demo-app/env/lib/python3.10/site-packages/redis/connection.py", line 429, in read_from_socket
    raise ConnectionError(SERVER_CLOSED_CONNECTION_ERROR)
redis.exceptions.ConnectionError: Connection closed by server.

During handling of the above exception, another exception occurred:

Traceback (most recent call last):
  File "/home/intellisys/Desktop/demo-app/env/lib/python3.10/site-packages/redis/connection.py", line 559, in connect
    sock = self._connect()
  File "/home/intellisys/Desktop/demo-app/env/lib/python3.10/site-packages/redis/connection.py", line 615, in _connect
    raise err
  File "/home/intellisys/Desktop/demo-app/env/lib/python3.10/site-packages/redis/connection.py", line 603, in _connect
    sock.connect(socket_address)
ConnectionRefusedError: [Errno 111] Connection refused

During handling of the above exception, another exception occurred:

Traceback (most recent call last):
  File "/home/intellisys/Desktop/demo-app/env/lib/python3.10/site-packages/rq/worker.py", line 1020, in perform_job
    self.handle_job_success(job=job,
  File "/home/intellisys/Desktop/demo-app/env/lib/python3.10/site-packages/rq/worker.py", line 970, in handle_job_success
    pipeline.watch(job.dependents_key)
  File "/home/intellisys/Desktop/demo-app/env/lib/python3.10/site-packages/redis/client.py", line 4041, in watch
    return self.execute_command('WATCH', *names)
  File "/home/intellisys/Desktop/demo-app/env/lib/python3.10/site-packages/redis/client.py", line 3822, in execute_command
    return self.immediate_execute_command(*args, **kwargs)
  File "/home/intellisys/Desktop/demo-app/env/lib/python3.10/site-packages/redis/client.py", line 3836, in immediate_execute_command
    conn = self.connection_pool.get_connection(command_name,
  File "/home/intellisys/Desktop/demo-app/env/lib/python3.10/site-packages/redis/connection.py", line 1202, in get_connection
    connection.connect()
  File "/home/intellisys/Desktop/demo-app/env/lib/python3.10/site-packages/redis/connection.py", line 563, in connect
    raise ConnectionError(self._error_message(e))
redis.exceptions.ConnectionError: Error 111 connecting to localhost:11000. Connection refused.

19:10:26 Worker rq:worker:00aec4f18b64491ea60aab34d4f099f7: found an unhandled exception, quitting...
Traceback (most recent call last):
  File "/home/intellisys/Desktop/demo-app/env/lib/python3.10/site-packages/redis/connection.py", line 1198, in get_connection
    if connection.can_read():
  File "/home/intellisys/Desktop/demo-app/env/lib/python3.10/site-packages/redis/connection.py", line 734, in can_read
    return self._parser.can_read(timeout)
  File "/home/intellisys/Desktop/demo-app/env/lib/python3.10/site-packages/redis/connection.py", line 416, in can_read
    return self.read_from_socket(timeout=timeout,
  File "/home/intellisys/Desktop/demo-app/env/lib/python3.10/site-packages/redis/connection.py", line 429, in read_from_socket
    raise ConnectionError(SERVER_CLOSED_CONNECTION_ERROR)
redis.exceptions.ConnectionError: Connection closed by server.

During handling of the above exception, another exception occurred:

Traceback (most recent call last):
  File "/home/intellisys/Desktop/demo-app/env/lib/python3.10/site-packages/redis/connection.py", line 559, in connect
    sock = self._connect()
  File "/home/intellisys/Desktop/demo-app/env/lib/python3.10/site-packages/redis/connection.py", line 615, in _connect
    raise err
  File "/home/intellisys/Desktop/demo-app/env/lib/python3.10/site-packages/redis/connection.py", line 603, in _connect
    sock.connect(socket_address)
ConnectionRefusedError: [Errno 111] Connection refused

During handling of the above exception, another exception occurred:

Traceback (most recent call last):
  File "/home/intellisys/Desktop/demo-app/env/lib/python3.10/site-packages/rq/worker.py", line 595, in work
    self.execute_job(job, queue)
  File "/home/intellisys/Desktop/demo-app/env/lib/python3.10/site-packages/rq/worker.py", line 856, in execute_job
    self.monitor_work_horse(job, queue)
  File "/home/intellisys/Desktop/demo-app/env/lib/python3.10/site-packages/rq/worker.py", line 818, in monitor_work_horse
    self.set_current_job_working_time(0)
  File "/home/intellisys/Desktop/demo-app/env/lib/python3.10/site-packages/rq/worker.py", line 382, in set_current_job_working_time
    connection.hset(self.key, 'current_job_working_time', current_job_working_time)
  File "/home/intellisys/Desktop/demo-app/env/lib/python3.10/site-packages/redis/client.py", line 3050, in hset
    return self.execute_command('HSET', name, *items)
  File "/home/intellisys/Desktop/demo-app/env/lib/python3.10/site-packages/redis/client.py", line 898, in execute_command
    conn = self.connection or pool.get_connection(command_name, **options)
  File "/home/intellisys/Desktop/demo-app/env/lib/python3.10/site-packages/redis/connection.py", line 1202, in get_connection
    connection.connect()
  File "/home/intellisys/Desktop/demo-app/env/lib/python3.10/site-packages/redis/connection.py", line 563, in connect
    raise ConnectionError(self._error_message(e))
redis.exceptions.ConnectionError: Error 111 connecting to localhost:11000. Connection refused.
Traceback (most recent call last):
  File "/home/intellisys/Desktop/demo-app/env/lib/python3.10/site-packages/redis/connection.py", line 559, in connect
    sock = self._connect()
  File "/home/intellisys/Desktop/demo-app/env/lib/python3.10/site-packages/redis/connection.py", line 615, in _connect
    raise err
  File "/home/intellisys/Desktop/demo-app/env/lib/python3.10/site-packages/redis/connection.py", line 603, in _connect
    sock.connect(socket_address)
ConnectionRefusedError: [Errno 111] Connection refused

During handling of the above exception, another exception occurred:

Traceback (most recent call last):
  File "/usr/lib/python3.10/runpy.py", line 196, in _run_module_as_main
    return _run_code(code, main_globals, None,
  File "/usr/lib/python3.10/runpy.py", line 86, in _run_code
    exec(code, run_globals)
  File "/home/intellisys/Desktop/demo-app/apps/frappe/frappe/utils/bench_helper.py", line 110, in <module>
    main()
  File "/home/intellisys/Desktop/demo-app/apps/frappe/frappe/utils/bench_helper.py", line 20, in main
    click.Group(commands=commands)(prog_name="bench")
  File "/home/intellisys/Desktop/demo-app/env/lib/python3.10/site-packages/click/core.py", line 829, in __call__
    return self.main(*args, **kwargs)
  File "/home/intellisys/Desktop/demo-app/env/lib/python3.10/site-packages/click/core.py", line 782, in main
    rv = self.invoke(ctx)
  File "/home/intellisys/Desktop/demo-app/env/lib/python3.10/site-packages/click/core.py", line 1259, in invoke
    return _process_result(sub_ctx.command.invoke(sub_ctx))
  File "/home/intellisys/Desktop/demo-app/env/lib/python3.10/site-packages/click/core.py", line 1259, in invoke
    return _process_result(sub_ctx.command.invoke(sub_ctx))
  File "/home/intellisys/Desktop/demo-app/env/lib/python3.10/site-packages/click/core.py", line 1066, in invoke
    return ctx.invoke(self.callback, **ctx.params)
  File "/home/intellisys/Desktop/demo-app/env/lib/python3.10/site-packages/click/core.py", line 610, in invoke
    return callback(*args, **kwargs)
  File "/home/intellisys/Desktop/demo-app/apps/frappe/frappe/commands/scheduler.py", line 203, in start_worker
    start_worker(queue, quiet=quiet)
  File "/home/intellisys/Desktop/demo-app/apps/frappe/frappe/utils/background_jobs.py", line 196, in start_worker
    Worker(queues, name=get_worker_name(queue)).work(logging_level=logging_level)
  File "/home/intellisys/Desktop/demo-app/env/lib/python3.10/site-packages/rq/worker.py", line 626, in work
    self.register_death()
  File "/home/intellisys/Desktop/demo-app/env/lib/python3.10/site-packages/rq/worker.py", line 326, in register_death
    p.execute()
  File "/home/intellisys/Desktop/demo-app/env/lib/python3.10/site-packages/redis/client.py", line 4012, in execute
    conn = self.connection_pool.get_connection('MULTI',
  File "/home/intellisys/Desktop/demo-app/env/lib/python3.10/site-packages/redis/connection.py", line 1192, in get_connection
    connection.connect()
  File "/home/intellisys/Desktop/demo-app/env/lib/python3.10/site-packages/redis/connection.py", line 563, in connect
    raise ConnectionError(self._error_message(e))
redis.exceptions.ConnectionError: Error 111 connecting to localhost:11000. Connection refused.
/home/intellisys/Desktop/demo-app/apps/frappe/frappe/build.py:7: DeprecationWarning: The distutils package is deprecated and slated for removal in Python 3.12. Use setuptools or check PEP 632 for potential alternatives
  from distutils.spawn import find_executable
/home/intellisys/Desktop/demo-app/env/lib/python3.10/site-packages/botocore/httpsession.py:18: DeprecationWarning: 'urllib3.contrib.pyopenssl' module is deprecated and will be removed in a future release of urllib3 2.x. Read more in this issue: https://github.com/urllib3/urllib3/issues/2680
  from urllib3.contrib.pyopenssl import orig_util_SSLContext as SSLContext
/home/intellisys/Desktop/demo-app/env/lib/python3.10/site-packages/botocore/httpsession.py:18: DeprecationWarning: 'urllib3.contrib.pyopenssl' module is deprecated and will be removed in a future release of urllib3 2.x. Read more in this issue: https://github.com/urllib3/urllib3/issues/2680
  from urllib3.contrib.pyopenssl import orig_util_SSLContext as SSLContext
/home/intellisys/Desktop/demo-app/env/lib/python3.10/site-packages/botocore/httpsession.py:18: DeprecationWarning: 'urllib3.contrib.pyopenssl' module is deprecated and will be removed in a future release of urllib3 2.x. Read more in this issue: https://github.com/urllib3/urllib3/issues/2680
  from urllib3.contrib.pyopenssl import orig_util_SSLContext as SSLContext
/home/intellisys/Desktop/demo-app/apps/frappe/frappe/build.py:7: DeprecationWarning: The distutils package is deprecated and slated for removal in Python 3.12. Use setuptools or check PEP 632 for potential alternatives
  from distutils.spawn import find_executable
Traceback (most recent call last):
  File "/home/intellisys/Desktop/demo-app/env/lib/python3.10/site-packages/redis/connection.py", line 559, in connect
    sock = self._connect()
  File "/home/intellisys/Desktop/demo-app/env/lib/python3.10/site-packages/redis/connection.py", line 615, in _connect
    raise err
  File "/home/intellisys/Desktop/demo-app/env/lib/python3.10/site-packages/redis/connection.py", line 603, in _connect
    sock.connect(socket_address)
ConnectionRefusedError: [Errno 111] Connection refused

During handling of the above exception, another exception occurred:

Traceback (most recent call last):
  File "/usr/lib/python3.10/runpy.py", line 196, in _run_module_as_main
    return _run_code(code, main_globals, None,
  File "/usr/lib/python3.10/runpy.py", line 86, in _run_code
    exec(code, run_globals)
  File "/home/intellisys/Desktop/demo-app/apps/frappe/frappe/utils/bench_helper.py", line 110, in <module>
    main()
  File "/home/intellisys/Desktop/demo-app/apps/frappe/frappe/utils/bench_helper.py", line 20, in main
    click.Group(commands=commands)(prog_name="bench")
  File "/home/intellisys/Desktop/demo-app/env/lib/python3.10/site-packages/click/core.py", line 829, in __call__
    return self.main(*args, **kwargs)
  File "/home/intellisys/Desktop/demo-app/env/lib/python3.10/site-packages/click/core.py", line 782, in main
    rv = self.invoke(ctx)
  File "/home/intellisys/Desktop/demo-app/env/lib/python3.10/site-packages/click/core.py", line 1259, in invoke
    return _process_result(sub_ctx.command.invoke(sub_ctx))
  File "/home/intellisys/Desktop/demo-app/env/lib/python3.10/site-packages/click/core.py", line 1259, in invoke
    return _process_result(sub_ctx.command.invoke(sub_ctx))
  File "/home/intellisys/Desktop/demo-app/env/lib/python3.10/site-packages/click/core.py", line 1066, in invoke
    return ctx.invoke(self.callback, **ctx.params)
  File "/home/intellisys/Desktop/demo-app/env/lib/python3.10/site-packages/click/core.py", line 610, in invoke
    return callback(*args, **kwargs)
  File "/home/intellisys/Desktop/demo-app/apps/frappe/frappe/commands/scheduler.py", line 203, in start_worker
    start_worker(queue, quiet=quiet)
  File "/home/intellisys/Desktop/demo-app/apps/frappe/frappe/utils/background_jobs.py", line 196, in start_worker
    Worker(queues, name=get_worker_name(queue)).work(logging_level=logging_level)
  File "/home/intellisys/Desktop/demo-app/env/lib/python3.10/site-packages/rq/worker.py", line 627, in work
    self.unsubscribe()
  File "/home/intellisys/Desktop/demo-app/env/lib/python3.10/site-packages/rq/worker.py", line 532, in unsubscribe
    self.pubsub.unsubscribe()
  File "/home/intellisys/Desktop/demo-app/env/lib/python3.10/site-packages/redis/client.py", line 3600, in unsubscribe
    return self.execute_command('UNSUBSCRIBE', *args)
  File "/home/intellisys/Desktop/demo-app/env/lib/python3.10/site-packages/redis/client.py", line 3466, in execute_command
    self.connection = self.connection_pool.get_connection(
  File "/home/intellisys/Desktop/demo-app/env/lib/python3.10/site-packages/redis/connection.py", line 1192, in get_connection
    connection.connect()
  File "/home/intellisys/Desktop/demo-app/env/lib/python3.10/site-packages/redis/connection.py", line 563, in connect
    raise ConnectionError(self._error_message(e))
redis.exceptions.ConnectionError: Error 111 connecting to localhost:11000. Connection refused.
/home/intellisys/Desktop/demo-app/apps/frappe/frappe/build.py:7: DeprecationWarning: The distutils package is deprecated and slated for removal in Python 3.12. Use setuptools or check PEP 632 for potential alternatives
  from distutils.spawn import find_executable
Traceback (most recent call last):
Exception in thread   File "/home/intellisys/Desktop/demo-app/env/lib/python3.10/site-packages/redis/connection.py", line 559, in connect
Thread-1:
Traceback (most recent call last):
  File "/usr/lib/python3.10/threading.py", line 1016, in _bootstrap_inner
    sock = self._connect()
  File "/home/intellisys/Desktop/demo-app/env/lib/python3.10/site-packages/redis/connection.py", line 615, in _connect
    self.run()
  File "/home/intellisys/Desktop/demo-app/env/lib/python3.10/site-packages/redis/client.py", line 3718, in run
    raise err
  File "/home/intellisys/Desktop/demo-app/env/lib/python3.10/site-packages/redis/connection.py", line 603, in _connect
    sock.connect(socket_address)    pubsub.get_message(ignore_subscribe_messages=True,

ConnectionRefusedError: [Errno 111] Connection refused

During handling of the above exception, another exception occurred:

Traceback (most recent call last):
  File "/usr/lib/python3.10/runpy.py", line 196, in _run_module_as_main
    return _run_code(code, main_globals, None,
  File "/usr/lib/python3.10/runpy.py", line 86, in _run_code
    exec(code, run_globals)
  File "/home/intellisys/Desktop/demo-app/apps/frappe/frappe/utils/bench_helper.py", line 110, in <module>
    main()
  File "/home/intellisys/Desktop/demo-app/apps/frappe/frappe/utils/bench_helper.py", line 20, in main
    click.Group(commands=commands)(prog_name="bench")
  File "/home/intellisys/Desktop/demo-app/env/lib/python3.10/site-packages/click/core.py", line 829, in __call__
    return self.main(*args, **kwargs)
  File "/home/intellisys/Desktop/demo-app/env/lib/python3.10/site-packages/click/core.py", line 782, in main
    rv = self.invoke(ctx)
  File "/home/intellisys/Desktop/demo-app/env/lib/python3.10/site-packages/click/core.py", line 1259, in invoke
    return _process_result(sub_ctx.command.invoke(sub_ctx))
  File "/home/intellisys/Desktop/demo-app/env/lib/python3.10/site-packages/click/core.py", line 1259, in invoke
    return _process_result(sub_ctx.command.invoke(sub_ctx))
  File "/home/intellisys/Desktop/demo-app/env/lib/python3.10/site-packages/click/core.py", line 1066, in invoke
    return ctx.invoke(self.callback, **ctx.params)
  File "/home/intellisys/Desktop/demo-app/env/lib/python3.10/site-packages/click/core.py", line 610, in invoke
    return callback(*args, **kwargs)
  File "/home/intellisys/Desktop/demo-app/apps/frappe/frappe/commands/scheduler.py", line 203, in start_worker
    start_worker(queue, quiet=quiet)
  File "/home/intellisys/Desktop/demo-app/apps/frappe/frappe/utils/background_jobs.py", line 196, in start_worker
    Worker(queues, name=get_worker_name(queue)).work(logging_level=logging_level)
  File "/home/intellisys/Desktop/demo-app/env/lib/python3.10/site-packages/rq/worker.py", line 626, in work
    self.register_death()
  File "/home/intellisys/Desktop/demo-app/env/lib/python3.10/site-packages/rq/worker.py", line 326, in register_death
    p.execute()
  File "/home/intellisys/Desktop/demo-app/env/lib/python3.10/site-packages/redis/client.py", line 4012, in execute
  File "/home/intellisys/Desktop/demo-app/env/lib/python3.10/site-packages/redis/client.py", line 3617, in get_message
        response = self.parse_response(block=False, timeout=timeout)
  File "/home/intellisys/Desktop/demo-app/env/lib/python3.10/site-packages/redis/client.py", line 3503, in parse_response
    if not block and not conn.can_read(timeout=timeout):
  File "/home/intellisys/Desktop/demo-app/env/lib/python3.10/site-packages/redis/connection.py", line 734, in can_read
    return self._parser.can_read(timeout)
  File "/home/intellisys/Desktop/demo-app/env/lib/python3.10/site-packages/redis/connection.py", line 416, in can_read
    conn = self.connection_pool.get_connection('MULTI',return self.read_from_socket(timeout=timeout,

  File "/home/intellisys/Desktop/demo-app/env/lib/python3.10/site-packages/redis/connection.py", line 1192, in get_connection
  File "/home/intellisys/Desktop/demo-app/env/lib/python3.10/site-packages/redis/connection.py", line 429, in read_from_socket
    raise ConnectionError(SERVER_CLOSED_CONNECTION_ERROR)
redis.exceptions.ConnectionError: Connection closed by server.
    connection.connect()
  File "/home/intellisys/Desktop/demo-app/env/lib/python3.10/site-packages/redis/connection.py", line 563, in connect
    raise ConnectionError(self._error_message(e))
redis.exceptions.ConnectionError: Error 111 connecting to localhost:11000. Connection refused.
